2023-10-17 19:40:06.833669: I tensorflow/core/platform/cpu_feature_guard.cc:141] Your CPU supports instructions that this TensorFlow binary was not compiled to use: SSE4.1 SSE4.2 AVX AVX2 FMA
2023-10-17 19:40:07.135352: E tensorflow/stream_executor/cuda/cuda_driver.cc:300] failed call to cuInit: CUDA_ERROR_NO_DEVICE: no CUDA-capable device is detected
2023-10-17 19:40:07.135454: I tensorflow/stream_executor/cuda/cuda_diagnostics.cc:150] kernel driver does not appear to be running on this host (semantics.inf.um.es): /proc/driver/nvidia/version does not exist
/home/galmagro/anaconda3/envs/openea/lib/python3.6/site-packages/tensorflow/python/framework/dtypes.py:523: FutureWarning: Passing (type, 1) or '1type' as a synonym of type is deprecated; in a future version of numpy, it will be understood as (type, (1,)) / '(1,)type'.
  _np_qint8 = np.dtype([("qint8", np.int8, 1)])
/home/galmagro/anaconda3/envs/openea/lib/python3.6/site-packages/tensorflow/python/framework/dtypes.py:524: FutureWarning: Passing (type, 1) or '1type' as a synonym of type is deprecated; in a future version of numpy, it will be understood as (type, (1,)) / '(1,)type'.
  _np_quint8 = np.dtype([("quint8", np.uint8, 1)])
/home/galmagro/anaconda3/envs/openea/lib/python3.6/site-packages/tensorflow/python/framework/dtypes.py:525: FutureWarning: Passing (type, 1) or '1type' as a synonym of type is deprecated; in a future version of numpy, it will be understood as (type, (1,)) / '(1,)type'.
  _np_qint16 = np.dtype([("qint16", np.int16, 1)])
/home/galmagro/anaconda3/envs/openea/lib/python3.6/site-packages/tensorflow/python/framework/dtypes.py:526: FutureWarning: Passing (type, 1) or '1type' as a synonym of type is deprecated; in a future version of numpy, it will be understood as (type, (1,)) / '(1,)type'.
  _np_quint16 = np.dtype([("quint16", np.uint16, 1)])
/home/galmagro/anaconda3/envs/openea/lib/python3.6/site-packages/tensorflow/python/framework/dtypes.py:527: FutureWarning: Passing (type, 1) or '1type' as a synonym of type is deprecated; in a future version of numpy, it will be understood as (type, (1,)) / '(1,)type'.
  _np_qint32 = np.dtype([("qint32", np.int32, 1)])
/home/galmagro/anaconda3/envs/openea/lib/python3.6/site-packages/tensorflow/python/framework/dtypes.py:532: FutureWarning: Passing (type, 1) or '1type' as a synonym of type is deprecated; in a future version of numpy, it will be understood as (type, (1,)) / '(1,)type'.
  np_resource = np.dtype([("resource", np.ubyte, 1)])
Process Process-3:
Traceback (most recent call last):
  File "/home/galmagro/anaconda3/envs/openea/lib/python3.6/multiprocessing/process.py", line 258, in _bootstrap
    self.run()
  File "/home/galmagro/anaconda3/envs/openea/lib/python3.6/multiprocessing/process.py", line 93, in run
    self._target(*self._args, **self._kwargs)
  File "/home/galmagro/OpenEA/src/openea/modules/train/batch.py", line 13, in generate_pos_batch_queue
    out_queue.put(generate_pos_batch(triple_list1, triple_list2, batch_size, step))
  File "<string>", line 2, in put
  File "/home/galmagro/anaconda3/envs/openea/lib/python3.6/multiprocessing/managers.py", line 757, in _callmethod
    kind, result = conn.recv()
  File "/home/galmagro/anaconda3/envs/openea/lib/python3.6/multiprocessing/connection.py", line 250, in recv
    buf = self._recv_bytes()
  File "/home/galmagro/anaconda3/envs/openea/lib/python3.6/multiprocessing/connection.py", line 407, in _recv_bytes
    buf = self._recv(4)
  File "/home/galmagro/anaconda3/envs/openea/lib/python3.6/multiprocessing/connection.py", line 379, in _recv
    chunk = read(handle, remaining)
ConnectionResetError: [Errno 104] Connection reset by peer
Traceback (most recent call last):
  File "/home/galmagro/anaconda3/envs/openea/lib/python3.6/site-packages/tensorflow/python/client/session.py", line 1334, in _do_call
    return fn(*args)
  File "/home/galmagro/anaconda3/envs/openea/lib/python3.6/site-packages/tensorflow/python/client/session.py", line 1319, in _run_fn
    options, feed_dict, fetch_list, target_list, run_metadata)
  File "/home/galmagro/anaconda3/envs/openea/lib/python3.6/site-packages/tensorflow/python/client/session.py", line 1407, in _call_tf_sessionrun
    run_metadata)
tensorflow.python.framework.errors_impl.InvalidArgumentError: Sampler's range is too small.
	 [[{{node triple_loss/nce_loss/LogUniformCandidateSampler}} = LogUniformCandidateSampler[num_sampled=4096, num_true=1, range_max=4026, seed=0, seed2=0, unique=true, _device="/job:localhost/replica:0/task:0/device:CPU:0"](triple_loss/nce_loss/Cast)]]

During handling of the above exception, another exception occurred:

Traceback (most recent call last):
  File "main_from_args.py", line 95, in <module>
    model.run()
  File "/home/galmagro/OpenEA/src/openea/models/neural/proje.py", line 106, in run
    self.launch_training_1epo(i, triple_steps, steps_tasks, training_batch_queue, None, None)
  File "/home/galmagro/OpenEA/src/openea/models/basic_model.py", line 207, in launch_training_1epo
    self.launch_triple_training_1epo(epoch, triple_steps, steps_tasks, training_batch_queue, neighbors1, neighbors2)
  File "/home/galmagro/OpenEA/src/openea/models/neural/proje.py", line 90, in launch_triple_training_1epo
    self.pos_ts: [x[2] for x in batch_pos]})
  File "/home/galmagro/anaconda3/envs/openea/lib/python3.6/site-packages/tensorflow/python/client/session.py", line 929, in run
    run_metadata_ptr)
  File "/home/galmagro/anaconda3/envs/openea/lib/python3.6/site-packages/tensorflow/python/client/session.py", line 1152, in _run
    feed_dict_tensor, options, run_metadata)
  File "/home/galmagro/anaconda3/envs/openea/lib/python3.6/site-packages/tensorflow/python/client/session.py", line 1328, in _do_run
    run_metadata)
  File "/home/galmagro/anaconda3/envs/openea/lib/python3.6/site-packages/tensorflow/python/client/session.py", line 1348, in _do_call
    raise type(e)(node_def, op, message)
tensorflow.python.framework.errors_impl.InvalidArgumentError: Sampler's range is too small.
	 [[node triple_loss/nce_loss/LogUniformCandidateSampler (defined at /home/galmagro/OpenEA/src/openea/models/neural/proje.py:71)  = LogUniformCandidateSampler[num_sampled=4096, num_true=1, range_max=4026, seed=0, seed2=0, unique=true, _device="/job:localhost/replica:0/task:0/device:CPU:0"](triple_loss/nce_loss/Cast)]]

Caused by op 'triple_loss/nce_loss/LogUniformCandidateSampler', defined at:
  File "main_from_args.py", line 94, in <module>
    model.init()
  File "/home/galmagro/OpenEA/src/openea/models/neural/proje.py", line 24, in init
    self._define_embed_graph()
  File "/home/galmagro/OpenEA/src/openea/models/neural/proje.py", line 71, in _define_embed_graph
    partition_strategy='div')
  File "/home/galmagro/anaconda3/envs/openea/lib/python3.6/site-packages/tensorflow/python/ops/nn_impl.py", line 1248, in nce_loss
    name=name)
  File "/home/galmagro/anaconda3/envs/openea/lib/python3.6/site-packages/tensorflow/python/ops/nn_impl.py", line 1046, in _compute_sampled_logits
    seed=seed)
  File "/home/galmagro/anaconda3/envs/openea/lib/python3.6/site-packages/tensorflow/python/ops/candidate_sampling_ops.py", line 145, in log_uniform_candidate_sampler
    seed2=seed2, name=name)
  File "/home/galmagro/anaconda3/envs/openea/lib/python3.6/site-packages/tensorflow/python/ops/gen_candidate_sampling_ops.py", line 652, in log_uniform_candidate_sampler
    range_max=range_max, seed=seed, seed2=seed2, name=name)
  File "/home/galmagro/anaconda3/envs/openea/lib/python3.6/site-packages/tensorflow/python/framework/op_def_library.py", line 787, in _apply_op_helper
    op_def=op_def)
  File "/home/galmagro/anaconda3/envs/openea/lib/python3.6/site-packages/tensorflow/python/util/deprecation.py", line 488, in new_func
    return func(*args, **kwargs)
  File "/home/galmagro/anaconda3/envs/openea/lib/python3.6/site-packages/tensorflow/python/framework/ops.py", line 3274, in create_op
    op_def=op_def)
  File "/home/galmagro/anaconda3/envs/openea/lib/python3.6/site-packages/tensorflow/python/framework/ops.py", line 1770, in __init__
    self._traceback = tf_stack.extract_stack()

InvalidArgumentError (see above for traceback): Sampler's range is too small.
	 [[node triple_loss/nce_loss/LogUniformCandidateSampler (defined at /home/galmagro/OpenEA/src/openea/models/neural/proje.py:71)  = LogUniformCandidateSampler[num_sampled=4096, num_true=1, range_max=4026, seed=0, seed2=0, unique=true, _device="/job:localhost/replica:0/task:0/device:CPU:0"](triple_loss/nce_loss/Cast)]]

