/home/galmagro/anaconda3/envs/openea/lib/python3.6/site-packages/tensorflow/python/framework/dtypes.py:523: FutureWarning: Passing (type, 1) or '1type' as a synonym of type is deprecated; in a future version of numpy, it will be understood as (type, (1,)) / '(1,)type'.
  _np_qint8 = np.dtype([("qint8", np.int8, 1)])
/home/galmagro/anaconda3/envs/openea/lib/python3.6/site-packages/tensorflow/python/framework/dtypes.py:524: FutureWarning: Passing (type, 1) or '1type' as a synonym of type is deprecated; in a future version of numpy, it will be understood as (type, (1,)) / '(1,)type'.
  _np_quint8 = np.dtype([("quint8", np.uint8, 1)])
/home/galmagro/anaconda3/envs/openea/lib/python3.6/site-packages/tensorflow/python/framework/dtypes.py:525: FutureWarning: Passing (type, 1) or '1type' as a synonym of type is deprecated; in a future version of numpy, it will be understood as (type, (1,)) / '(1,)type'.
  _np_qint16 = np.dtype([("qint16", np.int16, 1)])
/home/galmagro/anaconda3/envs/openea/lib/python3.6/site-packages/tensorflow/python/framework/dtypes.py:526: FutureWarning: Passing (type, 1) or '1type' as a synonym of type is deprecated; in a future version of numpy, it will be understood as (type, (1,)) / '(1,)type'.
  _np_quint16 = np.dtype([("quint16", np.uint16, 1)])
/home/galmagro/anaconda3/envs/openea/lib/python3.6/site-packages/tensorflow/python/framework/dtypes.py:527: FutureWarning: Passing (type, 1) or '1type' as a synonym of type is deprecated; in a future version of numpy, it will be understood as (type, (1,)) / '(1,)type'.
  _np_qint32 = np.dtype([("qint32", np.int32, 1)])
/home/galmagro/anaconda3/envs/openea/lib/python3.6/site-packages/tensorflow/python/framework/dtypes.py:532: FutureWarning: Passing (type, 1) or '1type' as a synonym of type is deprecated; in a future version of numpy, it will be understood as (type, (1,)) / '(1,)type'.
  np_resource = np.dtype([("resource", np.ubyte, 1)])
/home/galmagro/anaconda3/envs/openea/lib/python3.6/site-packages/pandas/core/internals/blocks.py:861: VisibleDeprecationWarning: Creating an ndarray from ragged nested sequences (which is a list-or-tuple of lists-or-tuples-or ndarrays with different lengths or shapes) is deprecated. If you meant to do this, you must specify 'dtype=object' when creating the ndarray
  arr_value = np.array(value)
WARNING:tensorflow:From /home/galmagro/OpenEA/src/openea/approaches/kdcoe.py:355: calling l2_normalize (from tensorflow.python.ops.nn_impl) with dim is deprecated and will be removed in a future version.
Instructions for updating:
dim is deprecated, use axis instead
2023-10-17 19:55:36.720420: I tensorflow/core/platform/cpu_feature_guard.cc:141] Your CPU supports instructions that this TensorFlow binary was not compiled to use: SSE4.1 SSE4.2 AVX AVX2 FMA
2023-10-17 19:55:36.904988: E tensorflow/stream_executor/cuda/cuda_driver.cc:300] failed call to cuInit: CUDA_ERROR_NO_DEVICE: no CUDA-capable device is detected
2023-10-17 19:55:36.905091: I tensorflow/stream_executor/cuda/cuda_diagnostics.cc:150] kernel driver does not appear to be running on this host (semantics.inf.um.es): /proc/driver/nvidia/version does not exist
Traceback (most recent call last):
  File "/home/galmagro/anaconda3/envs/openea/lib/python3.6/site-packages/tensorflow/python/client/session.py", line 1334, in _do_call
    return fn(*args)
  File "/home/galmagro/anaconda3/envs/openea/lib/python3.6/site-packages/tensorflow/python/client/session.py", line 1319, in _run_fn
    options, feed_dict, fetch_list, target_list, run_metadata)
  File "/home/galmagro/anaconda3/envs/openea/lib/python3.6/site-packages/tensorflow/python/client/session.py", line 1407, in _call_tf_sessionrun
    run_metadata)
tensorflow.python.framework.errors_impl.InvalidArgumentError: Incompatible shapes: [469,469] vs. [512,512]
	 [[{{node desc/Mul_6}} = Mul[T=DT_FLOAT, _device="/job:localhost/replica:0/task:0/device:CPU:0"](desc/MatMul, desc/Const)]]

During handling of the above exception, another exception occurred:

Traceback (most recent call last):
  File "main_from_args.py", line 95, in <module>
    model.run()
  File "/home/galmagro/OpenEA/src/openea/approaches/kdcoe.py", line 584, in run
    self.launch_desc_1epo(i)
  File "/home/galmagro/OpenEA/src/openea/approaches/kdcoe.py", line 535, in launch_desc_1epo
    self.desc2: desc_em2})
  File "/home/galmagro/anaconda3/envs/openea/lib/python3.6/site-packages/tensorflow/python/client/session.py", line 929, in run
    run_metadata_ptr)
  File "/home/galmagro/anaconda3/envs/openea/lib/python3.6/site-packages/tensorflow/python/client/session.py", line 1152, in _run
    feed_dict_tensor, options, run_metadata)
  File "/home/galmagro/anaconda3/envs/openea/lib/python3.6/site-packages/tensorflow/python/client/session.py", line 1328, in _do_run
    run_metadata)
  File "/home/galmagro/anaconda3/envs/openea/lib/python3.6/site-packages/tensorflow/python/client/session.py", line 1348, in _do_call
    raise type(e)(node_def, op, message)
tensorflow.python.framework.errors_impl.InvalidArgumentError: Incompatible shapes: [469,469] vs. [512,512]
	 [[node desc/Mul_6 (defined at /home/galmagro/OpenEA/src/openea/approaches/kdcoe.py:365)  = Mul[T=DT_FLOAT, _device="/job:localhost/replica:0/task:0/device:CPU:0"](desc/MatMul, desc/Const)]]

Caused by op 'desc/Mul_6', defined at:
  File "main_from_args.py", line 94, in <module>
    model.init()
  File "/home/galmagro/OpenEA/src/openea/approaches/kdcoe.py", line 84, in init
    self._define_desc_graph()
  File "/home/galmagro/OpenEA/src/openea/approaches/kdcoe.py", line 365, in _define_desc_graph
    indicator)) + 0.)) / self.desc_batch_size
  File "/home/galmagro/anaconda3/envs/openea/lib/python3.6/site-packages/tensorflow/python/ops/math_ops.py", line 203, in multiply
    return gen_math_ops.mul(x, y, name)
  File "/home/galmagro/anaconda3/envs/openea/lib/python3.6/site-packages/tensorflow/python/ops/gen_math_ops.py", line 5042, in mul
    "Mul", x=x, y=y, name=name)
  File "/home/galmagro/anaconda3/envs/openea/lib/python3.6/site-packages/tensorflow/python/framework/op_def_library.py", line 787, in _apply_op_helper
    op_def=op_def)
  File "/home/galmagro/anaconda3/envs/openea/lib/python3.6/site-packages/tensorflow/python/util/deprecation.py", line 488, in new_func
    return func(*args, **kwargs)
  File "/home/galmagro/anaconda3/envs/openea/lib/python3.6/site-packages/tensorflow/python/framework/ops.py", line 3274, in create_op
    op_def=op_def)
  File "/home/galmagro/anaconda3/envs/openea/lib/python3.6/site-packages/tensorflow/python/framework/ops.py", line 1770, in __init__
    self._traceback = tf_stack.extract_stack()

InvalidArgumentError (see above for traceback): Incompatible shapes: [469,469] vs. [512,512]
	 [[node desc/Mul_6 (defined at /home/galmagro/OpenEA/src/openea/approaches/kdcoe.py:365)  = Mul[T=DT_FLOAT, _device="/job:localhost/replica:0/task:0/device:CPU:0"](desc/MatMul, desc/Const)]]

